2024-09-25 10:37:14 [INFO] Question: which day apple share got more volume ?

2024-09-25 10:37:14 [INFO] Running PandasAI with local LLM...
2024-09-25 10:37:14 [INFO] Prompt ID: 8584a0e6-135f-4a32-9473-78adaac59c2c
2024-09-25 10:37:14 [INFO] Executing Pipeline: GenerateChatPipeline
2024-09-25 10:37:14 [INFO] Executing Step 0: ValidatePipelineInput
2024-09-25 10:37:14 [INFO] Executing Step 1: CacheLookup
2024-09-25 10:37:14 [INFO] Executing Step 2: PromptGeneration
2024-09-25 10:37:14 [INFO] Using prompt: <dataframe>
dfs[0]:1261x7
Date,Open,High,Low,Close,Adj Close,Volume
2017-10-27,44.634998,133.610001,118.809998,46.375,171.781143,108434400
2020-10-16,109.377502,92.970001,49.9175,74.357498,48.808968,74113000
2022-03-09,148.539993,127.940002,124.550003,116.599998,51.032669,108872000
</dataframe>




Update this initial code:
```python
# TODO: import the required dependencies
import pandas as pd

# Write code here

# Declare result var: 
type (possible values "string", "number", "dataframe", "plot"). Examples: { "type": "string", "value": f"The highest salary is {highest_salary}." } or { "type": "number", "value": 125 } or { "type": "dataframe", "value": pd.DataFrame({...}) } or { "type": "plot", "value": "temp_chart.png" }

```



### QUERY
 which day apple share got more volume ?


Variable `dfs: list[pd.DataFrame]` is already declared.

At the end, declare "result" variable as a dictionary of type and value.

If you are asked to plot a chart, use "matplotlib" for charts, save as png.


Generate python code and return full updated code:
2024-09-25 10:37:14 [INFO] Executing Step 3: CodeGenerator
2024-09-25 10:41:31 [INFO] HTTP Request: POST http://localhost:11434/v1/chat/completions "HTTP/1.1 200 OK"
2024-09-25 10:41:31 [INFO] Prompt used:
            <dataframe>
dfs[0]:1261x7
Date,Open,High,Low,Close,Adj Close,Volume
2017-10-27,44.634998,133.610001,118.809998,46.375,171.781143,108434400
2020-10-16,109.377502,92.970001,49.9175,74.357498,48.808968,74113000
2022-03-09,148.539993,127.940002,124.550003,116.599998,51.032669,108872000
</dataframe>




Update this initial code:
```python
# TODO: import the required dependencies
import pandas as pd

# Write code here

# Declare result var: 
type (possible values "string", "number", "dataframe", "plot"). Examples: { "type": "string", "value": f"The highest salary is {highest_salary}." } or { "type": "number", "value": 125 } or { "type": "dataframe", "value": pd.DataFrame({...}) } or { "type": "plot", "value": "temp_chart.png" }

```



### QUERY
 which day apple share got more volume ?


Variable `dfs: list[pd.DataFrame]` is already declared.

At the end, declare "result" variable as a dictionary of type and value.

If you are asked to plot a chart, use "matplotlib" for charts, save as png.


Generate python code and return full updated code:
            
2024-09-25 10:41:31 [INFO] Code generated:
            ```
            import pandas as pd
import matplotlib.pyplot as plt

dfs = [
    pd.DataFrame({
        "Date": ["2017-10-27", "2020-10-16", "2022-03-09"],
        "Open": [44.634998, 109.377502, 148.53],
        "High": [133.61, 92.97, 127.94],
        "Low": [118.80, 49.9, 124.55],
        "Close": [46.375, 74.357498, 116.6],
        "Adj Close": [171.78, 48.8, 51.03],
        "Volume": [10843400, 7411300, 108872000]
    })
]

# Find the day with the highest volume
max_volume = dfs[0]["Volume"]
best_day = dfs[0]["Date"][0]
for row in dfs:
    if row["Volume"] > max_volume:
        max_volume = row["Volume"]
        best_day = row["Date"][0]

result = {"type": "string", "value": f"The day with the highest volume is {best_day}."}

# Plot a chart showing the volume over time
plt.figure(figsize=(8, 6))
plt.plot(dfs[0]["Date"], dfs[0]["Volume"])
plt.xlabel("Date")
plt.ylabel("Volume")
plt.title("Apple Share Volume Over Time")
plt.savefig("apple_volume.png")

result = {"type": "plot", "value": "apple_volume.png"}
            ```
            
2024-09-25 10:41:31 [INFO] Executing Step 4: CachePopulation
2024-09-25 10:41:31 [INFO] Executing Step 5: CodeCleaning
2024-09-25 10:41:31 [INFO] Saving charts to C:\Users\hsai5\OneDrive\Documents\LLM projects\Audio_RAG_pandasAI\exports\charts\temp_chart.png
2024-09-25 10:41:31 [INFO] 
Code running:
```
max_volume = dfs[0]['Volume']
best_day = dfs[0]['Date'][0]
for row in dfs:
    if row['Volume'] > max_volume:
        max_volume = row['Volume']
        best_day = row['Date'][0]
result = {'type': 'string', 'value': f'The day with the highest volume is {best_day}.'}
plt.figure(figsize=(8, 6))
plt.plot(dfs[0]['Date'], dfs[0]['Volume'])
plt.xlabel('Date')
plt.ylabel('Volume')
plt.title('Apple Share Volume Over Time')
plt.savefig('C:/Users/hsai5/OneDrive/Documents/LLM projects/Audio_RAG_pandasAI/exports/charts/temp_chart.png')
result = {'type': 'plot', 'value': 'C:/Users/hsai5/OneDrive/Documents/LLM projects/Audio_RAG_pandasAI/exports/charts/temp_chart.png'}
        ```
2024-09-25 10:41:31 [INFO] Executing Step 6: CodeExecution
2024-09-25 10:41:31 [ERROR] Failed with error: Traceback (most recent call last):
  File "C:\Users\hsai5\anaconda3\envs\myenv\lib\site-packages\pandasai\pipelines\chat\code_execution.py", line 85, in execute
    result = self.execute_code(code_to_run, code_context)
  File "C:\Users\hsai5\anaconda3\envs\myenv\lib\site-packages\pandasai\pipelines\chat\code_execution.py", line 171, in execute_code
    exec(code, environment)
  File "<string>", line 4, in <module>
  File "C:\Users\hsai5\anaconda3\envs\myenv\lib\site-packages\pandas\core\generic.py", line 1527, in __nonzero__
    raise ValueError(
ValueError: The truth value of a Series is ambiguous. Use a.empty, a.bool(), a.item(), a.any() or a.all().

2024-09-25 10:41:31 [WARNING] Failed to execute code retrying with a correction framework [retry number: 1]
2024-09-25 10:41:31 [INFO] Executing Pipeline: ErrorCorrectionPipeline
2024-09-25 10:41:31 [INFO] Executing Step 0: ErrorPromptGeneration
2024-09-25 10:41:31 [INFO] Using prompt: <dataframe>
dfs[0]:1261x7
Date,Open,High,Low,Close,Adj Close,Volume
2017-10-27,44.634998,133.610001,118.809998,46.375,171.781143,108434400
2020-10-16,109.377502,92.970001,49.9175,74.357498,48.808968,74113000
2022-03-09,148.539993,127.940002,124.550003,116.599998,51.032669,108872000
</dataframe>


The user asked the following question:
### QUERY
 which day apple share got more volume ?


You generated this python code:
max_volume = dfs[0]['Volume']
best_day = dfs[0]['Date'][0]
for row in dfs:
    if row['Volume'] > max_volume:
        max_volume = row['Volume']
        best_day = row['Date'][0]
result = {'type': 'string', 'value': f'The day with the highest volume is {best_day}.'}
plt.figure(figsize=(8, 6))
plt.plot(dfs[0]['Date'], dfs[0]['Volume'])
plt.xlabel('Date')
plt.ylabel('Volume')
plt.title('Apple Share Volume Over Time')
plt.savefig('C:/Users/hsai5/OneDrive/Documents/LLM projects/Audio_RAG_pandasAI/exports/charts/temp_chart.png')
result = {'type': 'plot', 'value': 'C:/Users/hsai5/OneDrive/Documents/LLM projects/Audio_RAG_pandasAI/exports/charts/temp_chart.png'}

It fails with the following error:
Traceback (most recent call last):
  File "C:\Users\hsai5\anaconda3\envs\myenv\lib\site-packages\pandasai\pipelines\chat\code_execution.py", line 85, in execute
    result = self.execute_code(code_to_run, code_context)
  File "C:\Users\hsai5\anaconda3\envs\myenv\lib\site-packages\pandasai\pipelines\chat\code_execution.py", line 171, in execute_code
    exec(code, environment)
  File "<string>", line 4, in <module>
  File "C:\Users\hsai5\anaconda3\envs\myenv\lib\site-packages\pandas\core\generic.py", line 1527, in __nonzero__
    raise ValueError(
ValueError: The truth value of a Series is ambiguous. Use a.empty, a.bool(), a.item(), a.any() or a.all().


Fix the python code above and return the new python code:
2024-09-25 10:41:31 [INFO] Executing Step 1: CodeGenerator
2024-09-25 10:45:32 [INFO] HTTP Request: POST http://localhost:11434/v1/chat/completions "HTTP/1.1 200 OK"
2024-09-25 10:45:32 [INFO] Prompt used:
            <dataframe>
dfs[0]:1261x7
Date,Open,High,Low,Close,Adj Close,Volume
2017-10-27,44.634998,133.610001,118.809998,46.375,171.781143,108434400
2020-10-16,109.377502,92.970001,49.9175,74.357498,48.808968,74113000
2022-03-09,148.539993,127.940002,124.550003,116.599998,51.032669,108872000
</dataframe>


The user asked the following question:
### QUERY
 which day apple share got more volume ?


You generated this python code:
max_volume = dfs[0]['Volume']
best_day = dfs[0]['Date'][0]
for row in dfs:
    if row['Volume'] > max_volume:
        max_volume = row['Volume']
        best_day = row['Date'][0]
result = {'type': 'string', 'value': f'The day with the highest volume is {best_day}.'}
plt.figure(figsize=(8, 6))
plt.plot(dfs[0]['Date'], dfs[0]['Volume'])
plt.xlabel('Date')
plt.ylabel('Volume')
plt.title('Apple Share Volume Over Time')
plt.savefig('C:/Users/hsai5/OneDrive/Documents/LLM projects/Audio_RAG_pandasAI/exports/charts/temp_chart.png')
result = {'type': 'plot', 'value': 'C:/Users/hsai5/OneDrive/Documents/LLM projects/Audio_RAG_pandasAI/exports/charts/temp_chart.png'}

It fails with the following error:
Traceback (most recent call last):
  File "C:\Users\hsai5\anaconda3\envs\myenv\lib\site-packages\pandasai\pipelines\chat\code_execution.py", line 85, in execute
    result = self.execute_code(code_to_run, code_context)
  File "C:\Users\hsai5\anaconda3\envs\myenv\lib\site-packages\pandasai\pipelines\chat\code_execution.py", line 171, in execute_code
    exec(code, environment)
  File "<string>", line 4, in <module>
  File "C:\Users\hsai5\anaconda3\envs\myenv\lib\site-packages\pandas\core\generic.py", line 1527, in __nonzero__
    raise ValueError(
ValueError: The truth value of a Series is ambiguous. Use a.empty, a.bool(), a.item(), a.any() or a.all().


Fix the python code above and return the new python code:
            
2024-09-25 10:45:32 [INFO] Code generated:
            ```
            max_volume = dfs['Volume'].iloc[0]
best_day = dfs['Date'].iloc[0]

for index, row in dfs.iterrows():
    if row['Volume'] > max_volume:
        max_volume = row['Volume']
        best_day = row['Date']

result = {'type': 'string', 'value': f'The day with the highest volume is {best_day}.'}

# Assuming you want to create a plot for all data, not just one specific column.
plt.figure(figsize=(8, 6))
plt.plot(dfs['Date'], dfs['Volume'])
plt.xlabel('Date')
plt.ylabel('Volume')
plt.title('Apple Share Volume Over Time')
plt.savefig('C:/Users/hsai5/OneDrive/Documents/LLM projects/Audio_RAG_pandasAI/exports/charts/temp_chart.png')

result = {'type': 'plot', 'value': 'C:/Users/hsai5/OneDrive/Documents/LLM projects/Audio_RAG_pandasAI/exports/charts/temp_chart.png'}
            ```
            
2024-09-25 10:45:32 [INFO] Executing Step 2: CodeCleaning
2024-09-25 10:45:32 [INFO] Saving charts to C:\Users\hsai5\OneDrive\Documents\LLM projects\Audio_RAG_pandasAI\exports\charts\temp_chart.png
2024-09-25 10:45:32 [INFO] 
Code running:
```
max_volume = dfs['Volume'].iloc[0]
best_day = dfs['Date'].iloc[0]
for index, row in dfs.iterrows():
    if row['Volume'] > max_volume:
        max_volume = row['Volume']
        best_day = row['Date']
result = {'type': 'string', 'value': f'The day with the highest volume is {best_day}.'}
plt.figure(figsize=(8, 6))
plt.plot(dfs['Date'], dfs['Volume'])
plt.xlabel('Date')
plt.ylabel('Volume')
plt.title('Apple Share Volume Over Time')
plt.savefig('C:/Users/hsai5/OneDrive/Documents/LLM projects/Audio_RAG_pandasAI/exports/charts/temp_chart.png')
result = {'type': 'plot', 'value': 'C:/Users/hsai5/OneDrive/Documents/LLM projects/Audio_RAG_pandasAI/exports/charts/temp_chart.png'}
        ```
2024-09-25 10:45:32 [ERROR] Failed with error: Traceback (most recent call last):
  File "C:\Users\hsai5\anaconda3\envs\myenv\lib\site-packages\pandasai\pipelines\chat\code_execution.py", line 85, in execute
    result = self.execute_code(code_to_run, code_context)
  File "C:\Users\hsai5\anaconda3\envs\myenv\lib\site-packages\pandasai\pipelines\chat\code_execution.py", line 171, in execute_code
    exec(code, environment)
  File "<string>", line 1, in <module>
TypeError: list indices must be integers or slices, not str

2024-09-25 10:45:32 [WARNING] Failed to execute code retrying with a correction framework [retry number: 2]
2024-09-25 10:45:32 [INFO] Executing Pipeline: ErrorCorrectionPipeline
2024-09-25 10:45:32 [INFO] Executing Step 0: ErrorPromptGeneration
2024-09-25 10:45:32 [INFO] Using prompt: <dataframe>
dfs[0]:1261x7
Date,Open,High,Low,Close,Adj Close,Volume
2017-10-27,44.634998,133.610001,118.809998,46.375,171.781143,108434400
2020-10-16,109.377502,92.970001,49.9175,74.357498,48.808968,74113000
2022-03-09,148.539993,127.940002,124.550003,116.599998,51.032669,108872000
</dataframe>


The user asked the following question:
### QUERY
 which day apple share got more volume ?


You generated this python code:
max_volume = dfs['Volume'].iloc[0]
best_day = dfs['Date'].iloc[0]
for index, row in dfs.iterrows():
    if row['Volume'] > max_volume:
        max_volume = row['Volume']
        best_day = row['Date']
result = {'type': 'string', 'value': f'The day with the highest volume is {best_day}.'}
plt.figure(figsize=(8, 6))
plt.plot(dfs['Date'], dfs['Volume'])
plt.xlabel('Date')
plt.ylabel('Volume')
plt.title('Apple Share Volume Over Time')
plt.savefig('C:/Users/hsai5/OneDrive/Documents/LLM projects/Audio_RAG_pandasAI/exports/charts/temp_chart.png')
result = {'type': 'plot', 'value': 'C:/Users/hsai5/OneDrive/Documents/LLM projects/Audio_RAG_pandasAI/exports/charts/temp_chart.png'}

It fails with the following error:
Traceback (most recent call last):
  File "C:\Users\hsai5\anaconda3\envs\myenv\lib\site-packages\pandasai\pipelines\chat\code_execution.py", line 85, in execute
    result = self.execute_code(code_to_run, code_context)
  File "C:\Users\hsai5\anaconda3\envs\myenv\lib\site-packages\pandasai\pipelines\chat\code_execution.py", line 171, in execute_code
    exec(code, environment)
  File "<string>", line 1, in <module>
TypeError: list indices must be integers or slices, not str


Fix the python code above and return the new python code:
2024-09-25 10:45:32 [INFO] Executing Step 1: CodeGenerator
2024-09-25 10:48:37 [INFO] HTTP Request: POST http://localhost:11434/v1/chat/completions "HTTP/1.1 200 OK"
2024-09-25 10:48:37 [INFO] Prompt used:
            <dataframe>
dfs[0]:1261x7
Date,Open,High,Low,Close,Adj Close,Volume
2017-10-27,44.634998,133.610001,118.809998,46.375,171.781143,108434400
2020-10-16,109.377502,92.970001,49.9175,74.357498,48.808968,74113000
2022-03-09,148.539993,127.940002,124.550003,116.599998,51.032669,108872000
</dataframe>


The user asked the following question:
### QUERY
 which day apple share got more volume ?


You generated this python code:
max_volume = dfs['Volume'].iloc[0]
best_day = dfs['Date'].iloc[0]
for index, row in dfs.iterrows():
    if row['Volume'] > max_volume:
        max_volume = row['Volume']
        best_day = row['Date']
result = {'type': 'string', 'value': f'The day with the highest volume is {best_day}.'}
plt.figure(figsize=(8, 6))
plt.plot(dfs['Date'], dfs['Volume'])
plt.xlabel('Date')
plt.ylabel('Volume')
plt.title('Apple Share Volume Over Time')
plt.savefig('C:/Users/hsai5/OneDrive/Documents/LLM projects/Audio_RAG_pandasAI/exports/charts/temp_chart.png')
result = {'type': 'plot', 'value': 'C:/Users/hsai5/OneDrive/Documents/LLM projects/Audio_RAG_pandasAI/exports/charts/temp_chart.png'}

It fails with the following error:
Traceback (most recent call last):
  File "C:\Users\hsai5\anaconda3\envs\myenv\lib\site-packages\pandasai\pipelines\chat\code_execution.py", line 85, in execute
    result = self.execute_code(code_to_run, code_context)
  File "C:\Users\hsai5\anaconda3\envs\myenv\lib\site-packages\pandasai\pipelines\chat\code_execution.py", line 171, in execute_code
    exec(code, environment)
  File "<string>", line 1, in <module>
TypeError: list indices must be integers or slices, not str


Fix the python code above and return the new python code:
            
2024-09-25 10:48:37 [INFO] Code generated:
            ```
            max_volume = dfs['Volume'].max()
best_day = dfs.loc[dfs['Volume'].idxmax(), 'Date']

result = { 'type': 'string', 
           'value': f'The day with the highest volume is {best_day}.' }

# Plotting code remains the same:
plt.figure(figsize=(8, 6))
plt.plot(dfs['Date'], dfs['Volume'])
plt.xlabel('Date')
plt.ylabel('Volume')
plt.title('Apple Share Volume Over Time')
plt.savefig('C:/Users/hsai5/OneDrive/Documents/LLM projects/Audio_RAG_pandasAI/exports/charts/temp_chart.png')

result = { 'type': 'plot', 
           'value': 'C:/Users/hsai5/OneDrive/Documents/LLM projects/Audio_RAG_pandasAI/exports/charts/temp_chart.png' }
            ```
            
2024-09-25 10:48:37 [INFO] Executing Step 2: CodeCleaning
2024-09-25 10:48:37 [INFO] Saving charts to C:\Users\hsai5\OneDrive\Documents\LLM projects\Audio_RAG_pandasAI\exports\charts\temp_chart.png
2024-09-25 10:48:37 [INFO] 
Code running:
```
max_volume = dfs['Volume'].max()
best_day = dfs.loc[dfs['Volume'].idxmax(), 'Date']
result = {'type': 'string', 'value': f'The day with the highest volume is {best_day}.'}
plt.figure(figsize=(8, 6))
plt.plot(dfs['Date'], dfs['Volume'])
plt.xlabel('Date')
plt.ylabel('Volume')
plt.title('Apple Share Volume Over Time')
plt.savefig('C:/Users/hsai5/OneDrive/Documents/LLM projects/Audio_RAG_pandasAI/exports/charts/temp_chart.png')
result = {'type': 'plot', 'value': 'C:/Users/hsai5/OneDrive/Documents/LLM projects/Audio_RAG_pandasAI/exports/charts/temp_chart.png'}
        ```
2024-09-25 10:48:37 [ERROR] Failed with error: Traceback (most recent call last):
  File "C:\Users\hsai5\anaconda3\envs\myenv\lib\site-packages\pandasai\pipelines\chat\code_execution.py", line 85, in execute
    result = self.execute_code(code_to_run, code_context)
  File "C:\Users\hsai5\anaconda3\envs\myenv\lib\site-packages\pandasai\pipelines\chat\code_execution.py", line 171, in execute_code
    exec(code, environment)
  File "<string>", line 1, in <module>
TypeError: list indices must be integers or slices, not str

2024-09-25 10:48:37 [WARNING] Failed to execute code retrying with a correction framework [retry number: 3]
2024-09-25 10:48:37 [INFO] Executing Pipeline: ErrorCorrectionPipeline
2024-09-25 10:48:37 [INFO] Executing Step 0: ErrorPromptGeneration
2024-09-25 10:48:37 [INFO] Using prompt: <dataframe>
dfs[0]:1261x7
Date,Open,High,Low,Close,Adj Close,Volume
2017-10-27,44.634998,133.610001,118.809998,46.375,171.781143,108434400
2020-10-16,109.377502,92.970001,49.9175,74.357498,48.808968,74113000
2022-03-09,148.539993,127.940002,124.550003,116.599998,51.032669,108872000
</dataframe>


The user asked the following question:
### QUERY
 which day apple share got more volume ?


You generated this python code:
max_volume = dfs['Volume'].max()
best_day = dfs.loc[dfs['Volume'].idxmax(), 'Date']
result = {'type': 'string', 'value': f'The day with the highest volume is {best_day}.'}
plt.figure(figsize=(8, 6))
plt.plot(dfs['Date'], dfs['Volume'])
plt.xlabel('Date')
plt.ylabel('Volume')
plt.title('Apple Share Volume Over Time')
plt.savefig('C:/Users/hsai5/OneDrive/Documents/LLM projects/Audio_RAG_pandasAI/exports/charts/temp_chart.png')
result = {'type': 'plot', 'value': 'C:/Users/hsai5/OneDrive/Documents/LLM projects/Audio_RAG_pandasAI/exports/charts/temp_chart.png'}

It fails with the following error:
Traceback (most recent call last):
  File "C:\Users\hsai5\anaconda3\envs\myenv\lib\site-packages\pandasai\pipelines\chat\code_execution.py", line 85, in execute
    result = self.execute_code(code_to_run, code_context)
  File "C:\Users\hsai5\anaconda3\envs\myenv\lib\site-packages\pandasai\pipelines\chat\code_execution.py", line 171, in execute_code
    exec(code, environment)
  File "<string>", line 1, in <module>
TypeError: list indices must be integers or slices, not str


Fix the python code above and return the new python code:
2024-09-25 10:48:37 [INFO] Executing Step 1: CodeGenerator
2024-09-25 10:51:13 [INFO] HTTP Request: POST http://localhost:11434/v1/chat/completions "HTTP/1.1 200 OK"
2024-09-25 10:51:13 [INFO] Prompt used:
            <dataframe>
dfs[0]:1261x7
Date,Open,High,Low,Close,Adj Close,Volume
2017-10-27,44.634998,133.610001,118.809998,46.375,171.781143,108434400
2020-10-16,109.377502,92.970001,49.9175,74.357498,48.808968,74113000
2022-03-09,148.539993,127.940002,124.550003,116.599998,51.032669,108872000
</dataframe>


The user asked the following question:
### QUERY
 which day apple share got more volume ?


You generated this python code:
max_volume = dfs['Volume'].max()
best_day = dfs.loc[dfs['Volume'].idxmax(), 'Date']
result = {'type': 'string', 'value': f'The day with the highest volume is {best_day}.'}
plt.figure(figsize=(8, 6))
plt.plot(dfs['Date'], dfs['Volume'])
plt.xlabel('Date')
plt.ylabel('Volume')
plt.title('Apple Share Volume Over Time')
plt.savefig('C:/Users/hsai5/OneDrive/Documents/LLM projects/Audio_RAG_pandasAI/exports/charts/temp_chart.png')
result = {'type': 'plot', 'value': 'C:/Users/hsai5/OneDrive/Documents/LLM projects/Audio_RAG_pandasAI/exports/charts/temp_chart.png'}

It fails with the following error:
Traceback (most recent call last):
  File "C:\Users\hsai5\anaconda3\envs\myenv\lib\site-packages\pandasai\pipelines\chat\code_execution.py", line 85, in execute
    result = self.execute_code(code_to_run, code_context)
  File "C:\Users\hsai5\anaconda3\envs\myenv\lib\site-packages\pandasai\pipelines\chat\code_execution.py", line 171, in execute_code
    exec(code, environment)
  File "<string>", line 1, in <module>
TypeError: list indices must be integers or slices, not str


Fix the python code above and return the new python code:
            
2024-09-25 10:51:13 [INFO] Code generated:
            ```
            max_volume = dfs['Volume'].max()
best_day = dfs.loc[dfs['Volume'].idxmax(), 'Date']
result = {'type': 'string', 'value': f'The day with the highest volume is {best_day}.'}

import matplotlib.pyplot as plt

plt.figure(figsize=(8, 6))
plt.plot(dfs['Date'], dfs['Volume'])
plt.xlabel('Date')
plt.ylabel('Volume')
plt.title('Apple Share Volume Over Time')
plt.savefig('C:/Users/hsai5/OneDrive/Documents/LLM projects/Audio_RAG_pandasAI/exports/charts/temp_chart.png')

result = {'type': 'plot', 'value': 'C:/Users/hsai5/OneDrive/Documents/LLM projects/Audio_RAG_pandasAI/exports/charts/temp_chart.png'}
            ```
            
2024-09-25 10:51:13 [INFO] Executing Step 2: CodeCleaning
2024-09-25 10:51:13 [INFO] Saving charts to C:\Users\hsai5\OneDrive\Documents\LLM projects\Audio_RAG_pandasAI\exports\charts\temp_chart.png
2024-09-25 10:51:13 [INFO] 
Code running:
```
max_volume = dfs['Volume'].max()
best_day = dfs.loc[dfs['Volume'].idxmax(), 'Date']
result = {'type': 'string', 'value': f'The day with the highest volume is {best_day}.'}
plt.figure(figsize=(8, 6))
plt.plot(dfs['Date'], dfs['Volume'])
plt.xlabel('Date')
plt.ylabel('Volume')
plt.title('Apple Share Volume Over Time')
plt.savefig('C:/Users/hsai5/OneDrive/Documents/LLM projects/Audio_RAG_pandasAI/exports/charts/temp_chart.png')
result = {'type': 'plot', 'value': 'C:/Users/hsai5/OneDrive/Documents/LLM projects/Audio_RAG_pandasAI/exports/charts/temp_chart.png'}
        ```
2024-09-25 10:51:13 [ERROR] Failed with error: Traceback (most recent call last):
  File "C:\Users\hsai5\anaconda3\envs\myenv\lib\site-packages\pandasai\pipelines\chat\code_execution.py", line 85, in execute
    result = self.execute_code(code_to_run, code_context)
  File "C:\Users\hsai5\anaconda3\envs\myenv\lib\site-packages\pandasai\pipelines\chat\code_execution.py", line 171, in execute_code
    exec(code, environment)
  File "<string>", line 1, in <module>
TypeError: list indices must be integers or slices, not str

2024-09-25 10:51:13 [ERROR] Pipeline failed on step 6: list indices must be integers or slices, not str
